<?xml version="1.0"?>
<robot>

  <link name="pole_link">
    <visual>
       <origin xyz="0 0 0" rpy="0 0 0" />
       <geometry>
         <cylinder radius="0.001" length="0.075"/>
       </geometry>
    </visual>

    <collision>
       <origin xyz="0 0 0" rpy="0 0 0" />
       <geometry>
         <cylinder radius="0.001" length="0.075"/>
       </geometry>
    </collision>

    <inertial>
      <mass value="0.001"/>
      <inertia ixx="0.001" ixy="0" ixz="0" iyy="0.001" iyz="0" izz="0.001"/>
    </inertial>
  </link>

  <link name="flag_link">
    <visual>
      <origin xyz="-0.022 0 0" rpy="0 0 0"/>
      <geometry>
        <box size="0.045 0.001 0.03"/>
      </geometry>
    </visual>
    <inertial>
      <mass value="0.001"/>
      <inertia ixx="0.001" ixy="0" ixz="0" iyy="0.001" iyz="0" izz="0.001"/>
    </inertial>
  </link>

  <joint name="flag_pole_joint" type="continuous">
    <axis xyz="0 0 1"/>
    <origin xyz="0 0 0.02" rpy="0 0 0" />
    <parent link="pole_link"/>
    <child link="flag_link" />
  </joint>

  <joint name="pole_base_joint" type="fixed">
    <origin xyz="-0.22 0.06 0.038" rpy="0 0 0" />
    <parent link="base_link"/>
    <child link="pole_link" />
  </joint>

</robot>
